<?xml version="1.0"?>

<robot name="URA">

  <link name="sub_link">
    <inertial>
      <origin
              xyz="0 0 0"
              rpy="0 0 0" />
      <mass value="0.148202375101878" />
      <inertia
              ixx="0"
              ixy="0"
              ixz="0"
              iyy="0"
              iyz="0"
              izz="0" />
    </inertial>
    <visual>
      <origin
              xyz="0 0 0"
              rpy="0 0 0" />
      <geometry>
        <mesh filename="package://proc_ura/meshes/base.STL" />
      </geometry>
      <material
              name="">
        <color rgba="0 0 0 1" />
      </material>
    </visual>
    <collision>
      <origin
              xyz="0 0 0"
              rpy="0 0 0" />
      <geometry>
        <mesh filename="package://proc_ura/meshes/base.STL" />
      </geometry>
    </collision>
  </link>

  <link name="base_link">
    <inertial>
      <origin
              xyz="0 0.0131024540957446 0"
              rpy="0 0 0" />
      <mass value="0.0450140458134961" />
      <inertia
              ixx="0"
              ixy="0"
              ixz="0"
              iyy="0"
              iyz="0"
              izz="0" />
    </inertial>
    <visual>
      <origin
              xyz="0 0 0"
              rpy="0 0 0" />
      <geometry>
        <mesh filename="package://proc_ura/meshes/Fix.STL" />
      </geometry>
      <material name="">
        <color rgba="0.501960784313725 0.501960784313725 0.501960784313725 1" />
      </material>
    </visual>
    <collision>
      <origin
              xyz="0 0 0"
              rpy="0 0 0" />
      <geometry>
        <mesh filename="package://proc_ura/meshes/Fix.STL" />
      </geometry>
    </collision>
  </link>

  <link name="bottom_link">
    <inertial>
      <origin
              xyz="-0.0128263293227892 -0.0659453769006113 1.42109472112326E-06"
              rpy="0 0 0" />
      <mass value="0.207119682952531" />
      <inertia
              ixx="0"
              ixy="0"
              ixz="0"
              iyy="0"
              iyz="0"
              izz="0" />
    </inertial>
    <visual>
      <origin
              xyz="0 0 0"
              rpy="0 0 0" />
      <geometry>
        <mesh filename="package://proc_ura/meshes/J1.STL" />
      </geometry>
      <material name="">
        <color rgba="0.501960784313725 0.501960784313725 0.501960784313725 1" />
      </material>
    </visual>
    <collision>
      <origin
              xyz="0 0 0"
              rpy="0 0 0" />
      <geometry>
        <mesh filename="package://proc_ura/meshes/J1.STL" />
      </geometry>
    </collision>
  </link>

  <link name="mid_link">
    <inertial>
      <origin
              xyz="-4.22065026380166E-06 -0.0238427685332122 0.0552904026319393"
              rpy="0 0 0" />
      <mass value="0.318160127525053" />
      <inertia
              ixx="0"
              ixy="0"
              ixz="0"
              iyy="0"
              iyz="0"
              izz="0" />
    </inertial>
    <visual>
      <origin
              xyz="0 0 0"
              rpy="0 0 0" />
      <geometry>
        <mesh filename="package://proc_ura/meshes/J2.STL" />
      </geometry>
      <material name="">
        <color rgba="0.501960784313725 0.501960784313725 0.501960784313725 1" />
      </material>
    </visual>
    <collision>
      <origin
              xyz="0 0 0"
              rpy="0 0 0" />
      <geometry>
        <mesh filename="package://proc_ura/meshes/J2.STL" />
      </geometry>
    </collision>
  </link>

  <link name="top_link">
    <inertial>
      <origin
              xyz="0.00733884120646397 -0.000738490660792937 -0.0304327162411585"
              rpy="0 0 0" />
      <mass value="0.102709673564339" />
      <inertia
              ixx="0"
              ixy="0"
              ixz="0"
              iyy="0"
              iyz="0"
              izz="0" />
    </inertial>
    <visual>
      <origin
              xyz="0 0 0"
              rpy="0 0 0" />
      <geometry>
        <mesh filename="package://proc_ura/meshes/J3.STL" />
      </geometry>
      <material name="">
        <color rgba="0.501960784313725 0.501960784313725 0.501960784313725 1" />
      </material>
    </visual>
    <collision>
      <origin
              xyz="0 0 0"
              rpy="0 0 0" />
      <geometry>
        <mesh filename="package://proc_ura/meshes/J3.STL" />
      </geometry>
    </collision>
  </link>

  <link name="tool_link">
    <inertial>
      <origin
              xyz="4.67319894364993E-06 0.0695571755660441 -0.0262184509373798"
              rpy="0 0 0" />
      <mass value="0.105976928601757" />
      <inertia
              ixx="0"
              ixy="0"
              ixz="0"
              iyy="0"
              iyz="0"
              izz="0" />
    </inertial>
    <visual>
      <origin
              xyz="0 0 0"
              rpy="0 0 0" />
      <geometry>
        <mesh filename="package://proc_ura/meshes/J4.STL" />
      </geometry>
      <material name="">
        <color rgba="0.501960784313725 0.501960784313725 0.501960784313725 1" />
      </material>
    </visual>
    <collision>
      <origin
              xyz="0 0 0"
              rpy="0 0 0" />
      <geometry>
        <mesh filename="package://proc_ura/meshes/J4.STL" />
      </geometry>
    </collision>
  </link>

  <link name="clamp_link">
    <inertial>
      <origin
              xyz="-0.0422442225463169 0.0228184321520898 -0.0265207786803975"
              rpy="0 0 0" />
      <mass value="0.0884654244685185" />
      <inertia
              ixx="0"
              ixy="0"
              ixz="0"
              iyy="0"
              iyz="0"
              izz="0" />
    </inertial>
    <visual>
      <origin xyz="0 0 0" rpy="0 0 0" />
      <geometry>
        <mesh filename="package://proc_ura/meshes/clamp.STL" />
      </geometry>
      <material name="">
        <color rgba="0.501960784313725 0.501960784313725 0.501960784313725 1" />
      </material>
    </visual>
    <collision>
      <origin xyz="0 0 0" rpy="0 0 0" />
      <geometry>
        <mesh filename="package://proc_ura/meshes/clamp.STL" />
      </geometry>
    </collision>
  </link>

  <joint name="base_joint" type="fixed">
    <origin xyz="0.015325 0 0.004025" rpy="1.5708 0 0"/>
    <parent link="sub_link"/>
    <child link="base_link"/>
    <axis xyz="0 0 0" />
  </joint>

  <joint name="base_rotation_joint" type="revolute">
    <origin xyz="0 0.02254 0" rpy="0 2.625 -3.1416" />
    <parent link="base_link" />
    <child link="bottom_link" />
    <axis xyz="0 -1 0" />
    <limit lower="0" upper="5.23" effort="10" velocity="10"/>
    <dynamics damping="1" friction="0"/>
  </joint>

  <joint name="bottom_joint" type="revolute">
    <origin xyz="-0.042 -0.086849 0" rpy="1.5708 0 1.5708" />
    <parent link="bottom_link" />
    <child link="mid_link" />
    <axis xyz="0 -1 0" />
    <limit lower="0.9" upper="4.39" effort="10" velocity="10"/>
    <dynamics damping="1" friction="0"/>
  </joint>

  <joint name="top_joint" type="revolute">
    <origin xyz="0 0 0.1524" rpy="3.1416 1.5708 -3.1416" />
    <parent link="mid_link" />
    <child link="top_link" />
    <axis xyz="0 1 0" />
    <limit lower="0.25" upper="4.5" effort="10" velocity="10"/>
    <dynamics damping="1" friction="0"/>
  </joint>

  <joint name="tool_joint" type="revolute">
    <origin xyz="0.016924 0 -0.062" rpy="3.1416 2.615 1.5708" />
    <parent link="top_link" />
    <child link="tool_link" />
    <axis xyz="0 1 0" />
    <limit lower="0" upper="5.23" effort="10" velocity="10"/>
    <dynamics damping="1" friction="0"/>
  </joint>

  <joint name="clamp_joint" type="revolute">
    <origin xyz="0 0.064598 -0.022252" rpy="1.5708 8.3267E-16 -1.1082" />
    <parent link="tool_link" />
    <child link="clamp_link" />
    <axis xyz="0 1 0" />
    <limit lower="0" upper="2.57" effort="10" velocity="10"/>
    <dynamics damping="1" friction="0"/>
  </joint>

  <!--<transmission name="tran1">-->
    <!--<type>transmission_interface/SimpleTransmission</type>-->
    <!--<joint name="base_rotation_joint">-->
      <!--<hardwareInterface>hardware_interface/PositionJointInterface</hardwareInterface>-->
    <!--</joint>-->
    <!--<actuator name="motor1">-->
      <!--<hardwareInterface>hardware_interface/PositionJointInterface</hardwareInterface>-->
      <!--<mechanicalReduction>1</mechanicalReduction>-->
    <!--</actuator>-->
  <!--</transmission>-->

  <!--<transmission name="tran1">-->
    <!--<type>transmission_interface/SimpleTransmission</type>-->
    <!--<joint name="bottom_joint">-->
      <!--<hardwareInterface>hardware_interface/PositionJointInterface</hardwareInterface>-->
    <!--</joint>-->
    <!--<actuator name="motor1">-->
      <!--<hardwareInterface>hardware_interface/PositionJointInterface</hardwareInterface>-->
      <!--<mechanicalReduction>1</mechanicalReduction>-->
    <!--</actuator>-->
  <!--</transmission>-->

  <!--<transmission name="tran1">-->
    <!--<type>transmission_interface/SimpleTransmission</type>-->
    <!--<joint name="top_joint">-->
      <!--<hardwareInterface>hardware_interface/PositionJointInterface</hardwareInterface>-->
    <!--</joint>-->
    <!--<actuator name="motor1">-->
      <!--<hardwareInterface>hardware_interface/PositionJointInterface</hardwareInterface>-->
      <!--<mechanicalReduction>1</mechanicalReduction>-->
    <!--</actuator>-->
  <!--</transmission>-->

  <!--<transmission name="tran1">-->
    <!--<type>transmission_interface/SimpleTransmission</type>-->
    <!--<joint name="tool_joint">-->
      <!--<hardwareInterface>hardware_interface/PositionJointInterface</hardwareInterface>-->
    <!--</joint>-->
    <!--<actuator name="motor1">-->
      <!--<hardwareInterface>hardware_interface/PositionJointInterface</hardwareInterface>-->
      <!--<mechanicalReduction>1</mechanicalReduction>-->
    <!--</actuator>-->
  <!--</transmission>-->

  <!--&lt;!&ndash; ros_control plugin &ndash;&gt;-->
  <!--<gazebo>-->
    <!--<plugin filename="libgazebo_ros_control.so" name="gazebo_ros_control">-->
      <!--<robotNamespace>/proc_ura</robotNamespace>-->
    <!--</plugin>-->
  <!--</gazebo>-->
</robot>