<?xml version="1.0"?>

<robot name="URA">

  <link name="world_link">
    <visual>
      <origin rpy="0 0 0" xyz=" 0 0 -0.025"/>
      <geometry>
        <box size="0.2 0.13 0.05"/>
      </geometry>
      <material name="Black"/>
    </visual>
    <collision>
      <origin rpy="0 0 0" xyz=" 0 0 -0.025"/>
      <geometry>
        <box size="0.2 0.13 0.05"/>
      </geometry>
    </collision>
  </link>

  <link name="base_link">
    <inertial>
      <origin
              xyz="0 0 0"
              rpy="0 0 0" />
      <mass value="0.0876288345931558" />
      <inertia
              ixx="0"
              ixy="0"
              ixz="0"
              iyy="0"
              iyz="0"
              izz="0" />
    </inertial>
    <visual>
      <origin
              xyz="0 0 0"
              rpy="0 0 0" />
      <geometry>
        <mesh filename="package://proc_ura/meshes/base.STL" />
      </geometry>
      <material name="">
        <color rgba="0.898039215686275 0.917647058823529 0.929411764705882 1" />
      </material>
    </visual>
    <collision>
      <origin
              xyz="0 0 0"
              rpy="0 0 0" />
      <geometry>
        <mesh filename="package://proc_ura/meshes/base.STL" />
      </geometry>
    </collision>
  </link>

  <link name="bottom_link">
    <inertial>
      <origin
              xyz="0 0.0255649685564661 -0.0151495692671234"
              rpy="0 0 0" />
      <mass value="0.736736484648281" />
      <inertia
              ixx="0.00133586238985065"
              ixy="0"
              ixz="0"
              iyy="0.00252483008288603"
              iyz="0.000331404297267385"
              izz="0.00198983437623005" />
    </inertial>
    <visual>
      <origin
              xyz="0 0 0"
              rpy="0 0 0" />
      <geometry>
        <mesh filename="package://proc_ura/meshes/J1.STL" />
      </geometry>
      <material name="">
        <color rgba="0.898039215686275 0.917647058823529 0.929411764705882 1" />
      </material>
    </visual>
    <collision>
      <origin
              xyz="0 0 0"
              rpy="0 0 0" />
      <geometry>
        <mesh filename="package://proc_ura/meshes/J1.STL" />
      </geometry>
    </collision>
  </link>

  <link name="mid_link">
    <inertial>
      <origin
              xyz="0 0 -0.101605221799065"
              rpy="0 0 0" />
      <mass value="0.109734997075546" />
      <inertia
              ixx="0.00052724215332117"
              ixy="0"
              ixz="0"
              iyy="0.000568700576805562"
              iyz="0"
              izz="0" />
    </inertial>
    <visual>
      <origin
              xyz="0 0 0"
              rpy="0 0 0" />
      <geometry>
        <mesh filename="package://proc_ura/meshes/J2.STL" />
      </geometry>
      <material name="">
        <color rgba="0.898039215686275 0.917647058823529 0.929411764705882 1" />
      </material>
    </visual>
    <collision>
      <origin
              xyz="0 0 0"
              rpy="0 0 0" />
      <geometry>
        <mesh filename="package://proc_ura/meshes/J2.STL" />
      </geometry>
    </collision>
  </link>

  <link name="top_link">
    <inertial>
      <origin
              xyz="0 0 -0.0810236012031487"
              rpy="0 0 0" />
      <mass value="0.530209842688532" />
      <inertia
              ixx="0.00245579139975232"
              ixy="0"
              ixz="0"
              iyy="0.00386029153565598"
              iyz="0"
              izz="0.00155754338447778" />
    </inertial>
    <visual>
      <origin
              xyz="0 0 0"
              rpy="0 0 0" />
      <geometry>
        <mesh filename="package://proc_ura/meshes/J3.STL" />
      </geometry>
      <material name="">
        <color rgba="0.898039215686275 0.917647058823529 0.929411764705882 1" />
      </material>
    </visual>
    <collision>
      <origin
              xyz="0 0 0"
              rpy="0 0 0" />
      <geometry>
        <mesh filename="package://proc_ura/meshes/J3.STL" />
      </geometry>
    </collision>
  </link>

  <link name="tool_link">
    <inertial>
      <origin
              xyz="0.0275876219543553 -0.00571431360971436 -0.0144223723249392"
              rpy="0 0 0" />
      <mass value="0.0825165692757006" />
      <inertia
              ixx="0"
              ixy="0"
              ixz="0"
              iyy="0"
              iyz="0"
              izz="0" />
    </inertial>
    <visual>
      <origin
              xyz="0 0 0"
              rpy="0 0 0" />
      <geometry>
        <mesh filename="package://proc_ura/meshes/J4.STL" />
      </geometry>
      <material name="">
        <color rgba="0.898039215686275 0.917647058823529 0.929411764705882 1" />
      </material>
    </visual>
    <collision>
      <origin
              xyz="0 0 0"
              rpy="0 0 0" />
      <geometry>
        <mesh filename="package://proc_ura/meshes/J4.STL" />
      </geometry>
    </collision>
  </link>

  <joint name="base_joint" type="fixed">
    <origin rpy="0 0 0" xyz="0 0 0"/>
    <parent link="world_link"/>
    <child link="base_link"/>
    <axis xyz="0 0 1" />
  </joint>

  <joint name="base_rotation_joint" type="revolute">
    <origin xyz="0 0 0.0235" rpy="1.5708 0 0" />
    <parent link="base_link" />
    <child link="bottom_link" />
    <axis xyz="0 1 0" />
    <limit lower="0" upper="5.23" effort="10" velocity="10"/>
    <dynamics damping="1" friction="0"/>
  </joint>

  <joint name="bottom_joint" type="revolute">
    <origin xyz="0 0.058884 -0.060428" rpy="1.3239 0 0" />
    <parent link="bottom_link" />
    <child link="mid_link" />
    <axis xyz="1 0 0" />
    <limit lower="0" upper="5.23" effort="10" velocity="10"/>
    <dynamics damping="1" friction="0"/>
  </joint>

  <joint name="top_joint" type="revolute">
    <origin xyz="0 0 -0.2032" rpy="1.2782 0 0" />
    <parent link="mid_link" />
    <child link="top_link" />
    <axis xyz="1 0 0" />
    <limit lower="0" upper="5.23" effort="10" velocity="10"/>
    <dynamics damping="1" friction="0"/>
  </joint>

  <joint name="tool_joint" type="revolute">
    <origin xyz="0.01785 0 -0.17158" rpy="0.010467 1.5708 0" />
    <parent link="top_link" />
    <child link="tool_link" />
    <axis xyz="1 0 0" />
    <limit lower="0" upper="5.23" effort="10" velocity="10"/>
    <dynamics damping="1" friction="0"/>
  </joint>

  <!--<transmission name="tran1">-->
    <!--<type>transmission_interface/SimpleTransmission</type>-->
    <!--<joint name="base_rotation_joint">-->
      <!--<hardwareInterface>hardware_interface/PositionJointInterface</hardwareInterface>-->
    <!--</joint>-->
    <!--<actuator name="motor1">-->
      <!--<hardwareInterface>hardware_interface/PositionJointInterface</hardwareInterface>-->
      <!--<mechanicalReduction>1</mechanicalReduction>-->
    <!--</actuator>-->
  <!--</transmission>-->

  <!--<transmission name="tran1">-->
    <!--<type>transmission_interface/SimpleTransmission</type>-->
    <!--<joint name="bottom_joint">-->
      <!--<hardwareInterface>hardware_interface/PositionJointInterface</hardwareInterface>-->
    <!--</joint>-->
    <!--<actuator name="motor1">-->
      <!--<hardwareInterface>hardware_interface/PositionJointInterface</hardwareInterface>-->
      <!--<mechanicalReduction>1</mechanicalReduction>-->
    <!--</actuator>-->
  <!--</transmission>-->

  <!--<transmission name="tran1">-->
    <!--<type>transmission_interface/SimpleTransmission</type>-->
    <!--<joint name="top_joint">-->
      <!--<hardwareInterface>hardware_interface/PositionJointInterface</hardwareInterface>-->
    <!--</joint>-->
    <!--<actuator name="motor1">-->
      <!--<hardwareInterface>hardware_interface/PositionJointInterface</hardwareInterface>-->
      <!--<mechanicalReduction>1</mechanicalReduction>-->
    <!--</actuator>-->
  <!--</transmission>-->

  <!--<transmission name="tran1">-->
    <!--<type>transmission_interface/SimpleTransmission</type>-->
    <!--<joint name="tool_joint">-->
      <!--<hardwareInterface>hardware_interface/PositionJointInterface</hardwareInterface>-->
    <!--</joint>-->
    <!--<actuator name="motor1">-->
      <!--<hardwareInterface>hardware_interface/PositionJointInterface</hardwareInterface>-->
      <!--<mechanicalReduction>1</mechanicalReduction>-->
    <!--</actuator>-->
  <!--</transmission>-->

  <!--&lt;!&ndash; ros_control plugin &ndash;&gt;-->
  <!--<gazebo>-->
    <!--<plugin filename="libgazebo_ros_control.so" name="gazebo_ros_control">-->
      <!--<robotNamespace>/proc_ura</robotNamespace>-->
    <!--</plugin>-->
  <!--</gazebo>-->
</robot>